Workbook

Sheet SQL
A1: ############################################
A2: ############################################
A4: ## Amount of events during given period 5242
A5: ## November 1998
A6: ## December 2340
A7: ## January 904
A8: SELECT
A9: user_pseudo_id,
A10: FORMAT_TIMESTAMP('%Y-%m-%d', TIMESTAMP_MICROS(event_timestamp)) AS event_date,
A11: event_name,
A12: purchase_revenue_in_usd,
A13: FROM
... A351: event_count DESC;

Sheet Purchase
A1: user_pseudo_id | B1: event_date | C1: event_name | D1: purchase_revenue_in_usd
A2: 3297046.7 | B2: 44136 | C2: purchase | D2: 87 | F2: Row Labels | G2: Count of event_date | J2: Count of event_date
A3: 6828468.2 | B3: 44136 | C3: purchase | D3: 46 | F3: 44136 | G3: 14 | I3: 44136 | J3: 14
A4: 4075022.3 | B4: 44136 | C4: purchase | D4: 13 | F4: 44137 | G4: 49 | I4: 44137 | J4: 49
A5: 70761379 | B5: 44136 | C5: purchase | D5: 32 | F5: 44138 | G5: 49 | I5: 44138 | J5: 49
A6: 33027284 | B6: 44136 | C6: purchase | D6: 63 | F6: 44139 | G6: 46 | I6: 44139 | J6: 46
A7: 68689240 | B7: 44136 | C7: purchase | D7: 59 | F7: 44140 | G7: 26 | I7: 44140 | J7: 26
A8: 40765277 | B8: 44136 | C8: purchase | D8: 48 | F8: 44141 | G8: 58 | I8: 44141 | J8: 58
A9: 2422026 | B9: 44136 | C9: purchase | D9: 72 | F9: 44142 | G9: 31 | I9: 44142 | J9: 31
A10: 29640693 | B10: 44136 | C10: purchase | D10: 55 | F10: 44143 | G10: 32 | I10: 44143 | J10: 32
A11: 29640693 | B11: 44136 | C11: purchase | D11: 59 | F11: 44144 | G11: 52 | I11: 44144 | J11: 52
A12: 36638696 | B12: 44136 | C12: purchase | D12: 34 | F12: 44145 | G12: 63 | I12: 44145 | J12: 63
A13: 1494018.5 | B13: 44136 | C13: purchase | D13: 25 | F13: 44146 | G13: 63 | I13: 44146 | J13: 63
A14: 7905299838 | B14: 44136 | C14: purchase | D14: 120 | F14: 44147 | G14: 54 | I14: 44147 | J14: 54
... A93: 81324083 | B93: 44138 | C93: purchase | D93: 120 | F93: 44226 | G93: 5 | I93: 44226 | J93: 5
A94: 8606659.8 | B94: 44138 | C94: purchase | D94: 12 | F94: Grand Total | G94: 5242
A95: 50924450 | B95: 44138 | C95: purchase | D95: 54
A96: 56494470 | B96: 44138 | C96: purchase | D96: 66
A97: 53709875 | B97: 44138 | C97: purchase | D97: 279
A98: 55484598 | B98: 44138 | C98: purchase | D98: 116
A99: 7757973.8 | B99: 44138 | C99: purchase | D99: 28
A100: 45473624 | B100: 44138 | C100: purchase | D100: 27
A101: 16187715 | B101: 44138 | C101: purchase | D101: 55
A102: 53887436 | B102: 44138 | C102: purchase | D102: 219
A103: 2798155.8 | B103: 44138 | C103: purchase | D103: 10
A104: 1257911.6 | B104: 44138 | C104: purchase | D104: 22
A105: 484269875 | B105: 44138 | C105: purchase | D105: 130
A106: 43166185 | B106: 44138 | C106: purchase | D106: 17
... A5243: 17220616 | B5243: 44226 | C5243: purchase | D5243: 28

Sheet Users
A1: event_date | B1: Count of users | C1: Purchasing users (from main query) | D1: Purchasing users (%)
A2: 44136 | B2: 2365 | C2: 14 | D2: =C2/B2 -> 0.0059196617
A3: 44137 | B3: 3134 | C3: 49 | D3: =C3/B3 -> 0.015634971
A4: 44138 | B4: 4342 | C4: 49 | D4: =C4/B4 -> 0.011285122
A5: 44139 | B5: 3314 | C5: 44 | D5: =C5/B5 -> 0.013277007
A6: 44140 | B6: 2825 | C6: 26 | D6: =C6/B6 -> 0.0092035398
A7: 44141 | B7: 2363 | C7: 58 | D7: =C7/B7 -> 0.02454507
A8: 44142 | B8: 1735 | C8: 31 | D8: =C8/B8 -> 0.017867435
A9: 44143 | B9: 1661 | C9: 32 | D9: =C9/B9 -> 0.019265503
A10: 44144 | B10: 2365 | C10: 52 | D10: =C10/B10 -> 0.021987315
A11: 44145 | B11: 2748 | C11: 62 | D11: =C11/B11 -> 0.022561863
A12: 44146 | B12: 2750 | C12: 63 | D12: =C12/B12 -> 0.022909091
A13: 44147 | B13: 2585 | C13: 52 | D13: =C13/B13 -> 0.020116054
... A30: 44164 | B30: 2418 | C30: 49 | D30: =C30/B30 -> 0.020264682
A31: 44165 | B31: 3211 | C31: 132 | D31: =C31/B31 -> 0.041108689 | E31: avg. | F31: =AVERAGE(D2:D31) -> 0.02396154
A32: 44166 | B32: 3480 | C32: 96 | D32: =C32/B32 -> 0.027586207
A33: 44167 | B33: 3307 | C33: 79 | D33: =C33/B33 -> 0.023888721
A34: 44168 | B34: 3634 | C34: 85 | D34: =C34/B34 -> 0.023390204
A35: 44169 | B35: 3366 | C35: 92 | D35: =C35/B35 -> 0.027332145
A36: 44170 | B36: 2575 | C36: 84 | D36: =C36/B36 -> 0.032621359
A37: 44171 | B37: 2461 | C37: 41 | D37: =C37/B37 -> 0.016659894
A38: 44172 | B38: 3855 | C38: 104 | D38: =C38/B38 -> 0.026977951
A39: 44173 | B39: 5659 | C39: 116 | D39: =C39/B39 -> 0.020498321
A40: 44174 | B40: 4559 | C40: 147 | D40: =C40/B40 -> 0.032243913
A41: 44175 | B41: 4279 | C41: 129 | D41: =C41/B41 -> 0.030147231
A42: 44176 | B42: 4045 | C42: 148 | D42: =C42/B42 -> 0.036588381
A43: 44177 | B43: 3211 | C43: 100 | D43: =C43/B43 -> 0.031142946
... A61: 44195 | B61: 2558 | C61: 22 | D61: =C61/B61 -> 0.0086004691
A62: 44196 | B62: 2143 | C62: 25 | D62: =C62/B62 -> 0.011665889 | F62: =AVERAGE(D32:D62) -> 0.021491987
A63: 44197 | B63: 1948 | C63: 14 | D63: =C63/B63 -> 0.0071868583
A64: 44198 | B64: 2341 | C64: 13 | D64: =C64/B64 -> 0.0055531824
A65: 44199 | B65: 2299 | C65: 13 | D65: =C65/B65 -> 0.0056546324
A66: 44200 | B66: 2681 | C66: 14 | D66: =C66/B66 -> 0.0052219321
A67: 44201 | B67: 3583 | C67: 28 | D67: =C67/B67 -> 0.0078146804
A68: 44202 | B68: 4803 | C68: 30 | D68: =C68/B68 -> 0.0062460962
A69: 44203 | B69: 3572 | C69: 22 | D69: =C69/B69 -> 0.0061590146
A70: 44204 | B70: 3254 | C70: 30 | D70: =C70/B70 -> 0.0092194222
A71: 44205 | B71: 2582 | C71: 19 | D71: =C71/B71 -> 0.0073586367
A72: 44206 | B72: 2433 | C72: 14 | D72: =C72/B72 -> 0.0057542129
A73: 44207 | B73: 3034 | C73: 26 | D73: =C73/B73 -> 0.0085695452
...

Sheet Revenue
A1: event_date | B1: total_revenue | C1: One-time users | D1: Returning customers | E1: =Users!C1 -> Purchasing users (from main query) | F1: Average order value | G1: Count of orders
A2: 44136 | B2: 773 | C2: 659 | D2: =B2-C2 -> 114 | E2: =Users!C2 -> 14 | F2: =B2/E2 -> 55.214286 | G2: =Purchase!J3 -> 14
A3: 44137 | B3: 4789 | C3: 3029 | D3: =B3-C3 -> 1760 | E3: =Users!C3 -> 49 | F3: =B3/E3 -> 97.734694 | G3: =Purchase!J4 -> 49
A4: 44138 | B4: 3313 | C4: 2645 | D4: =B4-C4 -> 668 | E4: =Users!C4 -> 49 | F4: =B4/E4 -> 67.612245 | G4: =Purchase!J5 -> 49
A5: 44139 | B5: 2197 | C5: 1186 | D5: =B5-C5 -> 1011 | E5: =Users!C5 -> 44 | F5: =B5/E5 -> 49.931818 | G5: =Purchase!J6 -> 46
A6: 44140 | B6: 1792 | C6: 1609 | D6: =B6-C6 -> 183 | E6: =Users!C6 -> 26 | F6: =B6/E6 -> 68.923077 | G6: =Purchase!J7 -> 26
A7: 44141 | B7: 3438 | C7: 2229 | D7: =B7-C7 -> 1209 | E7: =Users!C7 -> 58 | F7: =B7/E7 -> 59.275862 | G7: =Purchase!J8 -> 58
A8: 44142 | B8: 2531 | C8: 1680 | D8: =B8-C8 -> 851 | E8: =Users!C8 -> 31 | F8: =B8/E8 -> 81.645161 | G8: =Purchase!J9 -> 31
A9: 44143 | B9: 3760 | C9: 2420 | D9: =B9-C9 -> 1340 | E9: =Users!C9 -> 32 | F9: =B9/E9 -> 117.5 | G9: =Purchase!J10 -> 32
A10: 44144 | B10: 2154 | C10: 1324 | D10: =B10-C10 -> 830 | E10: =Users!C10 -> 52 | F10: =B10/E10 -> 41.423077 | G10: =Purchase!J11 -> 52
A11: 44145 | B11: 4041 | C11: 3376 | D11: =B11-C11 -> 665 | E11: =Users!C11 -> 62 | F11: =B11/E11 -> 65.177419 | G11: =Purchase!J12 -> 63
A12: 44146 | B12: 4428 | C12: 3420 | D12: =B12-C12 -> 1008 | E12: =Users!C12 -> 63 | F12: =B12/E12 -> 70.285714 | G12: =Purchase!J13 -> 63
A13: 44147 | B13: 3349 | C13: 2735 | D13: =B13-C13 -> 614 | E13: =Users!C13 -> 52 | F13: =B13/E13 -> 64.403846 | G13: =Purchase!J14 -> 54
... A20: 44154 | B20: 5752 | C20: 432 | D20: =B20-C20 -> 5320 | E20: =Users!C20 -> 79 | F20: =B20/E20 -> 72.810127 | G20: =Purchase!J21 -> 79
A21: 44155 | B21: 8792 | D21: =B21-C21 -> 8792 | E21: =Users!C21 -> 100 | F21: =B21/E21 -> 87.92 | G21: =Purchase!J22 -> 106
A22: 44156 | B22: 4336 | D22: =B22-C22 -> 4336 | E22: =Users!C22 -> 66 | F22: =B22/E22 -> 65.69697 | G22: =Purchase!J23 -> 66
A23: 44157 | B23: 3428 | D23: =B23-C23 -> 3428 | E23: =Users!C23 -> 58 | F23: =B23/E23 -> 59.103448 | G23: =Purchase!J24 -> 58
A24: 44158 | B24: 8482 | D24: =B24-C24 -> 8482 | E24: =Users!C24 -> 138 | F24: =B24/E24 -> 61.463768 | G24: =Purchase!J25 -> 138
A25: 44159 | B25: 10345 | C25: 3338 | D25: =B25-C25 -> 7007 | E25: =Users!C25 -> 120 | F25: =B25/E25 -> 86.208333 | G25: =Purchase!J26 -> 145
A26: 44160 | B26: 8121 | C26: 5159 | D26: =B26-C26 -> 2962 | E26: =Users!C26 -> 75 | F26: =B26/E26 -> 108.28 | G26: =Purchase!J27 -> 103
A27: 44161 | B27: 4133 | C27: 3547 | D27: =B27-C27 -> 586 | E27: =Users!C27 -> 47 | F27: =B27/E27 -> 87.93617 | G27: =Purchase!J28 -> 54
A28: 44162 | B28: 6699 | C28: 5026 | D28: =B28-C28 -> 1673 | E28: =Users!C28 -> 89 | F28: =B28/E28 -> 75.269663 | G28: =Purchase!J29 -> 93
A29: 44163 | B29: 6255 | C29: 4781 | D29: =B29-C29 -> 1474 | E29: =Users!C29 -> 69 | F29: =B29/E29 -> 90.652174 | G29: =Purchase!J30 -> 70
A30: 44164 | B30: 3862 | C30: 3270 | D30: =B30-C30 -> 592 | E30: =Users!C30 -> 49 | F30: =B30/E30 -> 78.816327 | G30: =Purchase!J31 -> 49
A31: 44165 | B31: 11990 | C31: 7900 | D31: =B31-C31 -> 4090 | E31: =Users!C31 -> 132 | F31: =B31/E31 -> 90.833333 | G31: =Purchase!J32 -> 136
A32: 44166 | B32: 6258 | C32: 4222 | D32: =B32-C32 -> 2036 | E32: =Users!C32 -> 96 | F32: =B32/E32 -> 65.1875 | G32: =Purchase!J33 -> 97
A33: 44167 | B33: 5201 | C33: 2912 | D33: =B33-C33 -> 2289 | E33: =Users!C33 -> 79 | F33: =B33/E33 -> 65.835443 | G33: =Purchase!J34 -> 78
A34: 44168 | B34: 4317 | C34: 3160 | D34: =B34-C34 -> 1157 | E34: =Users!C34 -> 85 | F34: =B34/E34 -> 50.788235 | G34: =Purchase!J35 -> 87
A35: 44169 | B35: 6458 | C35: 3946 | D35: =B35-C35 -> 2512 | E35: =Users!C35 -> 92 | F35: =B35/E35 -> 70.195652 | G35: =Purchase!J36 -> 93
A36: 44170 | B36: 6396 | C36: 4809 | D36: =B36-C36 -> 1587 | E36: =Users!C36 -> 84 | F36: =B36/E36 -> 76.142857 | G36: =Purchase!J37 -> 85
... A92: 44226 | B92: 159 | C92: 89 | D92: =B92-C92 -> 70 | E92: =Users!C92 -> 5 | F92: =B92/E92 -> 31.8 | G92: =Purchase!J93 -> 5
B94: 362165 | F94: =AVERAGE(F2:F92) -> 67.227535
F96: =AVERAGE(F2:F31) -> 74.453928
F97: =AVERAGE(F32:F62) -> 66.978905
F98: =AVERAGE(F63:F92) -> 60.258058

Sheet Time to purchase RAW
A1: user_pseudo_id | B1: session_start_event_date_time | C1: purchase_event_date_time | D1: event_value_in_usd | E1: time_to_purchase
A2: 36638696 | B2: 44136.007 | C2: 44136.019 | D2: 34 | E2: 1039
A3: 2422026 | B3: 44136.063 | C3: 44136.073 | D3: 72 | E3: 801
A4: 1494018.5 | B4: 44136.167 | C4: 44136.174 | D4: 25 | E4: 601
A5: 3297046.7 | B5: 44136.252 | C5: 44136.262 | D5: 87 | E5: 844
A6: 6828468.2 | B6: 44136.398 | C6: 44136.412 | D6: 46 | E6: 1244
A7: 33027284 | B7: 44136.455 | C7: 44136.463 | D7: 63 | E7: 724
A8: 38686208 | B8: 44136.428 | C8: 44136.513 | D8: 60 | E8: 7361
A9: 4075022.3 | B9: 44136.556 | C9: 44136.558 | D9: 13 | E9: 244
A10: 29640693 | B10: 44136.621 | C10: 44136.633 | D10: 55 | E10: 1104
A11: 29640693 | B11: 44136.621 | C11: 44136.642 | D11: 59 | E11: 1861
A12: 70761379 | B12: 44136.71 | C12: 44136.735 | D12: 32 | E12: 2191
A13: 68689240 | B13: 44136.726 | C13: 44136.737 | D13: 59 | E13: 1026
... A5087: 4661274.5 | B5087: 44226.894 | C5087: 44226.902 | D5087: 28 | E5087: 660
D5089: =SUM(D2:D5087) -> 347101 | E5089: =AVERAGE(E2:E5087) -> 4908.1573 | F5089: =TEXT(E5089/86400, "h:mm:ss") -> 1:21:48

Sheet Time to purchase agg
A1: purchase_date | B1: Revenue | C1: Avg.time to purchase (in seconds) | D1: count_purchases | E1: Avg.time to purchase (RHS, in minutes)
A2: 44136 | B2: 773 | C2: 1686.36 | D2: 14 | E2: =C2/60 -> 28.106 | G2: 2020-11 | H2: 4289.3098 | I2: =TEXT(H2/86400, "h:mm:ss") -> 1:11:29
A3: 44137 | B3: 4789 | C3: 4934.22 | D3: 49 | E3: =C3/60 -> 82.237 | G3: 2020-12 | H3: 5486.8187 | I3: =TEXT(H3/86400, "h:mm:ss") -> 1:31:27
A4: 44138 | B4: 3313 | C4: 5871.69 | D4: 49 | E4: =C4/60 -> 97.8615 | G4: 2021-01 | H4: 4744.4698 | I4: =TEXT(H4/86400, "h:mm:ss") -> 1:19:04
A5: 44139 | B5: 2013 | C5: 6973.8 | D5: 44 | E5: =C5/60 -> 116.23
A6: 44140 | B6: 1792 | C6: 2506.42 | D6: 26 | E6: =C6/60 -> 41.773667
A7: 44141 | B7: 3438 | C7: 5281 | D7: 58 | E7: =C7/60 -> 88.016667
A8: 44142 | B8: 2531 | C8: 1443.48 | D8: 31 | E8: =C8/60 -> 24.058
A9: 44143 | B9: 3760 | C9: 4042.66 | D9: 32 | E9: =C9/60 -> 67.377667
A10: 44144 | B10: 2154 | C10: 4690.54 | D10: 52 | E10: =C10/60 -> 78.175667
A11: 44145 | B11: 4014 | C11: 6244.23 | D11: 62 | E11: =C11/60 -> 104.0705
A12: 44146 | B12: 4428 | C12: 4916.46 | D12: 63 | E12: =C12/60 -> 81.941
A13: 44147 | B13: 3257 | C13: 5260.5 | D13: 52 | E13: =C13/60 -> 87.675
A14: 44148 | B14: 5831 | C14: 4243.13 | D14: 79 | E14: =C14/60 -> 70.718833
A15: 44149 | B15: 2338 | C15: 6264.97 | D15: 30 | E15: =C15/60 -> 104.41617
A16: 44150 | B16: 1483 | C16: 1624.1 | D16: 21 | E16: =C16/60 -> 27.068333
... A92: 44226 | B92: 159 | C92: 1043.8 | D92: 5 | E92: =C92/60 -> 17.396667
A94: Total | B94: =SUM(B2:B92) -> 347101 | D94: =SUM(D2:D92) -> 5086

Sheet Funnel Overview
F4: Total events count across all countries
C5: Event name | D5: Event count
C6: session_start | D6: 267116
C7: scroll | D7: 138098
C8: view_item | D8: 61252
C9: add_to_cart | D9: 12545
C10: add_payment_info | D10: 5751
C11: purchase | D11: 4419
C21: Event count (Absolute numbers) | J21: EVENT count (% drop from the previous step)
B22: Event order | C22: Event name | D22: Total | E22: US | F22: India | G22: Canada | I22: Event order | J22: Event name | K22: Total | L22: US | M22: India | N22: Canada
B23: 1 | C23: session_start | D23: 267116 | E23: 117160 | F23: 25059 | G23: 20037 | I23: 1 | J23: session_start | K23: =D23/D23 -> 1 | L23: =E23/E23 -> 1 | M23: =F23/F23 -> 1 | N23: =G23/G23 -> 1
B24: 2 | C24: scroll | D24: 138098 | E24: 60726 | F24: 13000 | G24: 10350 | I24: 2 | J24: scroll | K24: =(D24/D23)-1 -> -0.48300364 | L24: =(E24/E23)-1 -> -0.48168317 | M24: =(F24/F23)-1 -> -0.48122431 | N24: =(G24/G23)-1 -> -0.48345561
B25: 3 | C25: view_item | D25: 61252 | E25: 26953 | F25: 5795 | G25: 4653 | I25: 3 | J25: view_item | K25: =(D25/D24)-1 -> -0.55645991 | L25: =(E25/E24)-1 -> -0.55615387 | M25: =(F25/F24)-1 -> -0.55423077 | N25: =(G25/G24)-1 -> -0.55043478
B26: 4 | C26: add_to_cart | D26: 12545 | E26: 5603 | F26: 1162 | G26: 993 | I26: 4 | J26: add_to_cart | K26: =(D26/D25)-1 -> -0.79519036 | L26: =(E26/E25)-1 -> -0.79211962 | M26: =(F26/F25)-1 -> -0.79948231 | N26: =(G26/G25)-1 -> -0.7865893
B27: 5 | C27: add_payment_info | D27: 5751 | E27: 2516 | F27: 524 | G27: 465 | I27: 5 | J27: add_payment_info | K27: =(D27/D26)-1 -> -0.54157035 | L27: =(E27/E26)-1 -> -0.55095485 | M27: =(F27/F26)-1 -> -0.54905336 | N27: =(G27/G26)-1 -> -0.53172205
B28: 6 | C28: purchase | D28: 4419 | E28: 1942 | F28: 406 | G28: 355 | I28: 6 | J28: purchase | K28: =(D28/D27)-1 -> -0.23161189 | L28: =(E28/E27)-1 -> -0.2281399 | M28: =(F28/F27)-1 -> -0.22519084 | N28: =(G28/G27)-1 -> -0.23655914
B48: Insights
B49: ► Cleaned dataset consistet of more than 1.3 million events, within 270k unique accounts across 109 countries. Almost 500k interactions analysed within this funnel analysis
B50: ► Top 3 countries (US, India and Canada) accounts for 61% of total events and is representing roughly similar trends across each other and aggregate numbers.
B51: ► Bottle-neck check. Funnel element "add to chart" part falls drastically around 80% across all analysed geographies. Possible causes could be poor user interface, slow web, poor quality pictures of
B52: products and etc. Would recommend to look more deeply into this step (additional micro funnel and later on A/B testing based on gathered insights).
B53: ► Check for segmentation across the particular users, there might be more patterns with additional data analysis (mobile vs desktop buyers, gender or time spent in shop, different time periods)
B54: ► Figure out if marketing strategies are targeting correct audience.

Sheet Aggregate data
A1: user_pseudo_id | B1: session_start_event_date_time | C1: purchase_event_date_time | D1: purchase date | E1: category | F1: operating_system | G1: browser | H1: country | I1: event_value_in_usd | J1: time_to_purchase
A2: 36638696 | B2: 44136.007 | C2: 44136.019 | D2: =TEXT(C2, "yyyy-mm-dd") -> 2020-11-01 | E2: mobile | F2: Android | G2: Chrome | H2: United States | I2: 34 | J2: 1039 | N2: Sum of event_value_in_usd | O2: Column Labels | ED2: Purchasing users
A3: 2422026 | B3: 44136.063 | C3: 44136.073 | D3: =TEXT(C3, "yyyy-mm-dd") -> 2020-11-01 | E3: desktop | F3: Windows | G3: Chrome | H3: Sweden | I3: 72 | J3: 801 | N3: Row Labels | O3: desktop | P3: mobile | Q3: tablet | R3: Grand Total | U3: Desktop | V3: Mobile | W3: Tablet
A4: 1494018.5 | B4: 44136.167 | C4: 44136.174 | D4: =TEXT(C4, "yyyy-mm-dd") -> 2020-11-01 | E4: desktop | F4: Web | G4: Chrome | H4: Canada | I4: 25 | J4: 601 | N4: 2020-11-01 | O4: 566 | P4: 207 | R4: 773 | T4: 44136 | U4: 566 | V4: 207 | AG4: Count of user_pseudo_id | AH4: Column Labels
A5: 3297046.7 | B5: 44136.252 | C5: 44136.262 | D5: =TEXT(C5, "yyyy-mm-dd") -> 2020-11-01 | E5: desktop | F5: Web | G5: Chrome | H5: United States | I5: 87 | J5: 844 | N5: 2020-11-02 | O5: 3328 | P5: 1405 | Q5: 56 | R5: 4789 | T5: 44137 | U5: 3328 | V5: 1405 | W5: 56 | AG5: Row Labels | AH5: (not set) | AI5: Albania | AJ5: Algeria | AK5: Argentina | AL5: Armenia | AM5: Australia | AN5: Austria | AO5: Bahamas | AP5: Bahrain | AQ5: Bangladesh | AR5: Belarus | AS5: Belgium | AT5: Bolivia | AU5: Bosnia & Herzegovina | AV5: Brazil | AW5: Bulgaria | AX5: Cambodia | AY5: Canada | AZ5: Chile | BA5: China | BB5: Colombia | BC5: Costa Rica | BD5: Croatia | BE5: Cyprus | BF5: Czechia | BG5: Denmark | BH5: Dominican Republic | BI5: Ecuador | BJ5: Egypt | BK5: El Salvador | BL5: Finland | BM5: France | BN5: Georgia | BO5: Germany | BP5: Greece | BQ5: Guatemala | BR5: Honduras | BS5: Hong Kong | BT5: Hungary | BU5: India | BV5: Indonesia | BW5: Iraq | BX5: Ireland | BY5: Israel | BZ5: Italy | CA5: Japan | CB5: Jordan | CC5: Kazakhstan | CD5: Kenya | CE5: Kosovo | CF5: Kuwait | CG5: Latvia | CH5: Lebanon | CI5: Lithuania | CJ5: Luxembourg | CK5: Macao | CL5: Malaysia | CM5: Malta | CN5: Mexico | CO5: Mongolia | CP5: Morocco | CQ5: Netherlands | CR5: New Zealand | CS5: Nigeria | CT5: North Macedonia | CU5: Norway | CV5: Pakistan | CW5: Palestine | CX5: Panama | CY5: Paraguay | CZ5: Peru | DA5: Philippines | DB5: Poland | DC5: Portugal | DD5: Puerto Rico | DE5: Qatar | DF5: Romania | DG5: Russia | DH5: Saudi Arabia | DI5: Serbia | DJ5: Singapore | DK5: Slovakia | DL5: Slovenia | DM5: South Africa | DN5: South Korea | DO5: Spain | DP5: Sri Lanka | DQ5: Sweden | DR5: Switzerland | DS5: Taiwan | DT5: Thailand | DU5: Tunisia | DV5: Turkey | DW5: Ukraine | DX5: United Arab Emirates | DY5: United Kingdom | DZ5: United States | EA5: Uruguay | EB5: Venezuela | EC5: Vietnam | ED5: Grand Total
A6: 6828468.2 | B6: 44136.398 | C6: 44136.412 | D6: =TEXT(C6, "yyyy-mm-dd") -> 2020-11-01 | E6: mobile | F6: iOS | G6: Safari | H6: Belgium | I6: 46 | J6: 1244 | N6: 2020-11-03 | O6: 1992 | P6: 1321 | R6: 3313 | T6: 44138 | U6: 1992 | V6: 1321 | AG6: 2020-11-01 | AS6: 1 | AY6: 1 | CZ6: 2 | DO6: 1 | DQ6: 1 | DV6: 1 | DY6: 1 | DZ6: 6 | ED6: 14
A7: 33027284 | B7: 44136.455 | C7: 44136.463 | D7: =TEXT(C7, "yyyy-mm-dd") -> 2020-11-01 | E7: desktop | F7: Windows | G7: Chrome | H7: United Kingdom | I7: 63 | J7: 724 | N7: 2020-11-04 | O7: 1368 | P7: 623 | Q7: 22 | R7: 2013 | T7: 44139 | U7: 1368 | V7: 623 | W7: 22 | AG7: 2020-11-02 | AQ7: 1 | AV7: 1 | AY7: 7 | BA7: 1 | BU7: 7 | BZ7: 1 | CA7: 1 | CH7: 1 | CL7: 1 | DC7: 1 | DY7: 2 | DZ7: 24 | EC7: 1 | ED7: 49
A8: 38686208 | B8: 44136.428 | C8: 44136.513 | D8: =TEXT(C8, "yyyy-mm-dd") -> 2020-11-01 | E8: desktop | F8: Web | G8: <Other> | H8: Turkey | I8: 60 | J8: 7361 | N8: 2020-11-05 | O8: 975 | P8: 697 | Q8: 120 | R8: 1792 | T8: 44140 | U8: 975 | V8: 697 | W8: 120 | AG8: 2020-11-03 | AH8: 1 | AM8: 1 | AN8: 3 | AY8: 2 | BB8: 1 | BI8: 1 | BM8: 1 | BO8: 1 | BP8: 1 | BS8: 1 | BU8: 4 | CP8: 1 | DG8: 1 | DH8: 1 | DV8: 1 | DZ8: 27 | EC8: 1 | ED8: 49
A9: 4075022.3 | B9: 44136.556 | C9: 44136.558 | D9: =TEXT(C9, "yyyy-mm-dd") -> 2020-11-01 | E9: mobile | F9: Web | G9: Safari | H9: United States | I9: 13 | J9: 244 | N9: 2020-11-06 | O9: 1836 | P9: 1339 | Q9: 263 | R9: 3438 | T9: 44141 | U9: 1836 | V9: 1339 | W9: 263 | AG9: 2020-11-04 | AH9: 1 | AN9: 1 | AY9: 5 | BM9: 1 | BQ9: 1 | BU9: 5 | BX9: 1 | BY9: 1 | CL9: 1 | CV9: 1 | CZ9: 1 | DY9: 13 | DZ9: 11 | EC9: 1 | ED9: 44
A10: 29640693 | B10: 44136.621 | C10: 44136.633 | D10: =TEXT(C10, "yyyy-mm-dd") -> 2020-11-01 | E10: mobile | F10: Web | G10: Android Webview | H10: Peru | I10: 55 | J10: 1104 | N10: 2020-11-07 | O10: 1063 | P10: 1468 | R10: 2531 | T10: 44142 | U10: 1063 | V10: 1468 | AG10: 2020-11-05 | AV10: 1 | AY10: 2 | BF10: 1 | BO10: 1 | BU10: 2 | CM10: 1 | CS10: 1 | DC10: 1 | DJ10: 1 | DN10: 1 | DO10: 1 | DY10: 2 | DZ10: 11 | ED10: 26
A11: 29640693 | B11: 44136.621 | C11: 44136.642 | D11: =TEXT(C11, "yyyy-mm-dd") -> 2020-11-01 | E11: mobile | F11: Web | G11: Android Webview | H11: Peru | I11: 59 | J11: 1861 | N11: 2020-11-08 | O11: 2684 | P11: 892 | Q11: 184 | R11: 3760 | T11: 44143 | U11: 2684 | V11: 892 | W11: 184 | AG11: 2020-11-06 | AK11: 1 | AS11: 1 | AY11: 13 | BA11: 2 | BM11: 1 | BO11: 1 | BU11: 4 | BZ11: 2 | CQ11: 1 | CV11: 1 | DN11: 2 | DO11: 1 | DR11: 1 | DS11: 1 | DZ11: 26 | ED11: 58
A12: 70761379 | B12: 44136.71 | C12: 44136.735 | D12: =TEXT(C12, "yyyy-mm-dd") -> 2020-11-01 | E12: desktop | F12: Web | G12: Chrome | H12: Spain | I12: 32 | J12: 2191 | N12: 2020-11-09 | O12: 1152 | P12: 1002 | R12: 2154 | T12: 44144 | U12: 1152 | V12: 1002 | AG12: 2020-11-07 | AY12: 1 | BS12: 1 | BT12: 1 | BU12: 4 | CN12: 1 | DJ12: 2 | DN12: 1 | DQ12: 1 | DS12: 1 | DV12: 2 | DZ12: 16 | ED12: 31
A13: 68689240 | B13: 44136.726 | C13: 44136.737 | D13: =TEXT(C13, "yyyy-mm-dd") -> 2020-11-01 | E13: desktop | F13: Web | G13: Chrome | H13: United States | I13: 59 | J13: 1026 | N13: 2020-11-10 | O13: 2330 | P13: 1684 | R13: 4014 | T13: 44145 | U13: 2330 | V13: 1684 | AG13: 2020-11-08 | AM13: 1 | AP13: 1 | AY13: 1 | BA13: 2 | BP13: 1 | BU13: 5 | BX13: 1 | DB13: 2 | DC13: 1 | DZ13: 17 | ED13: 32
A14: 7905299838 | B14: 44136.816 | C14: 44136.866 | D14: =TEXT(C14, "yyyy-mm-dd") -> 2020-11-01 | E14: desktop | F14: <Other> | G14: Chrome | H14: United States | I14: 120 | J14: 4254 | N14: 2020-11-11 | O14: 1884 | P14: 2534 | Q14: 10 | R14: 4428 | T14: 44146 | U14: 1884 | V14: 2534 | W14: 10 | AG14: 2020-11-09 | AH14: 2 | AV14: 3 | AY14: 4 | BB14: 1 | BL14: 1 | BO14: 1 | BP14: 1 | BS14: 4 | BU14: 3 | BV14: 2 | BZ14: 1 | CA14: 1 | CN14: 1 | CQ14: 1 | DB14: 1 | DG14: 1 | DJ14: 2 | DO14: 3 | DY14: 1 | DZ14: 18 | ED14: 52
A15: 40765277 | B15: 44136.972 | C15: 44136.975 | D15: =TEXT(C15, "yyyy-mm-dd") -> 2020-11-01 | E15: desktop | F15: Web | G15: Chrome | H15: United States | I15: 48 | J15: 315 | N15: 2020-11-12 | O15: 1740 | P15: 1517 | R15: 3257 | T15: 44147 | U15: 1740 | V15: 1517 | AG15: 2020-11-10 | AH15: 2 | AV15: 1 | AY15: 3 | BA15: 2 | BI15: 1 | BJ15: 1 | BM15: 3 | BO15: 1 | BT15: 1 | BU15: 8 | BZ15: 1 | CA15: 2 | CN15: 1 | DG15: 1 | DH15: 1 | DL15: 1 | DN15: 2 | DS15: 2 | DV15: 1 | DY15: 2 | DZ15: 25 | ED15: 62
A16: 77977792 | B16: 44137.103 | C16: 44137.133 | D16: =TEXT(C16, "yyyy-mm-dd") -> 2020-11-02 | E16: desktop | F16: Web | G16: Chrome | H16: United States | I16: 65 | J16: 2624 | N16: 2020-11-13 | O16: 3203 | P16: 2628 | R16: 5831 | T16: 44148 | U16: 3203 | V16: 2628 | AG16: 2020-11-11 | AH16: 1 | AQ16: 1 | AY16: 9 | BA16: 1 | BM16: 1 | BO16: 2 | BU16: 5 | BY16: 1 | BZ16: 1 | CA16: 1 | CG16: 1 | CL16: 2 | CN16: 1 | CZ16: 1 | DA16: 1 | DG16: 1 | DS16: 2 | DW16: 1 | DY16: 3 | DZ16: 27 | ED16: 63
A17: 77977792 | B17: 44137.103 | C17: 44137.134 | D17: =TEXT(C17, "yyyy-mm-dd") -> 2020-11-02 | E17: desktop | F17: Web | G17: Chrome | H17: United States | I17: 65 | J17: 2695 | N17: 2020-11-14 | O17: 1482 | P17: 856 | R17: 2338 | T17: 44149 | U17: 1482 | V17: 856 | AG17: 2020-11-12 | AY17: 2 | BB17: 1 | BG17: 1 | BM17: 1 | BN17: 1 | BU17: 6 | BX17: 1 | BZ17: 2 | CL17: 2 | CQ17: 2 | DB17: 2 | DL17: 1 | DN17: 3 | DO17: 1 | DS17: 2 | DX17: 1 | DZ17: 23 | ED17: 52
A18: 91518233 | B18: 44137.147 | C18: 44137.157 | D18: =TEXT(C18, "yyyy-mm-dd") -> 2020-11-02 | E18: mobile | F18: Android | G18: Chrome | H18: Canada | I18: 67 | J18: 946 | N18: 2020-11-15 | O18: 1002 | P18: 307 | Q18: 174 | R18: 1483 | T18: 44150 | U18: 1002 | V18: 307 | W18: 174 | AG18: 2020-11-13 | AM18: 1 | AV18: 1 | AY18: 7 | BA18: 1 | BM18: 1 | BO18: 1 | BP18: 2 | BS18: 7 | BU18: 4 | BZ18: 1 | CA18: 1 | CL18: 1 | CP18: 1 | CQ18: 1 | CS18: 1 | CZ18: 1 | DA18: 1 | DC18: 1 | DJ18: 3 | DO18: 3 | DS18: 2 | DV18: 1 | DY18: 2 | DZ18: 34 | ED18: 79
A19: 91518233 | B19: 44137.147 | C19: 44137.165 | D19: =TEXT(C19, "yyyy-mm-dd") -> 2020-11-02 | E19: mobile | F19: Android | G19: Chrome | H19: Canada | I19: 90 | J19: 1583 | N19: 2020-11-16 | O19: 2362 | P19: 2518 | Q19: 96 | R19: 4976 | T19: 44151 | U19: 2362 | V19: 2518 | W19: 96 | AG19: 2020-11-14 | AM19: 1 | AY19: 4 | AZ19: 1 | BA19: 1 | BJ19: 1 | BM19: 2 | BO19: 1 | BU19: 1 | BV19: 1 | BZ19: 1 | CZ19: 1 | DD19: 1 | DG19: 1 | DT19: 1 | DV19: 1 | DY19: 1 | DZ19: 10 | ED19: 30
A20: 5448801.1 | B20: 44137.191 | C20: 44137.2 | D20: =TEXT(C20, "yyyy-mm-dd") -> 2020-11-02 | E20: mobile | F20: iOS | G20: Safari | H20: United States | I20: 38 | J20: 741 | N20: 2020-11-17 | O20: 3827 | P20: 2400 | R20: 6227 | T20: 44152 | U20: 3827 | V20: 2400 | AG20: 2020-11-15 | BA20: 1 | BM20: 2 | BU20: 3 | BX20: 1 | CL20: 1 | CT20: 1 | DO20: 1 | DT20: 1 | DZ20: 10 | ED20: 21
A21: 40418512 | B21: 44137.213 | C21: 44137.22 | D21: =TEXT(C21, "yyyy-mm-dd") -> 2020-11-02 | E21: mobile | F21: Web | G21: <Other> | H21: United States | I21: 24 | J21: 672 | N21: 2020-11-18 | O21: 2499 | P21: 2076 | R21: 4575 | T21: 44153 | U21: 2499 | V21: 2076 | AG21: 2020-11-16 | AY21: 6 | BF21: 1 | BM21: 2 | BU21: 6 | BY21: 2 | CA21: 1 | CD21: 1 | CH21: 1 | CN21: 1 | CR21: 1 | CZ21: 1 | DA21: 1 | DB21: 1 | DK21: 1 | DN21: 1 | DO21: 1 | DT21: 1 | DV21: 1 | DZ21: 35 | EC21: 2 | ED21: 67
A22: 41280452 | B22: 44137.245 | C22: 44137.264 | D22: =TEXT(C22, "yyyy-mm-dd") -> 2020-11-02 | E22: tablet | F22: iOS | G22: Safari | H22: India | I22: 56 | J22: 1665 | N22: 2020-11-19 | O22: 2361 | P22: 3391 | R22: 5752 | T22: 44154 | U22: 2361 | V22: 3391 | AG22: 2020-11-17 | AM22: 1 | AV22: 2 | AY22: 8 | BF22: 1 | BG22: 1 | BM22: 3 | BO22: 2 | BS22: 1 | BU22: 10 | BX22: 1 | BY22: 1 | CA22: 5 | CN22: 4 | CS22: 1 | DA22: 1 | DG22: 1 | DN22: 1 | DO22: 3 | DQ22: 2 | DS22: 3 | DT22: 1 | DU22: 1 | DY22: 2 | DZ22: 41 | EA22: 1 | ED22: 98
A23: 10295268 | B23: 44137.283 | C23: 44137.36 | D23: =TEXT(C23, "yyyy-mm-dd") -> 2020-11-02 | E23: desktop | F23: Web | G23: Chrome | H23: United States | I23: 127 | J23: 6679 | N23: 2020-11-20 | O23: 3566 | P23: 4310 | R23: 7876 | T23: 44155 | U23: 3566 | V23: 4310 | AG23: 2020-11-18 | AY23: 6 | BA23: 1 | BC23: 1 | BM23: 2 | BU23: 7 | BX23: 2 | BZ23: 2 | CQ23: 2 | CS23: 1 | CV23: 1 | DB23: 2 | DJ23: 3 | DY23: 1 | DZ23: 36 | ED23: 67
A24: 10295268 | B24: 44137.283 | C24: 44137.366 | D24: =TEXT(C24, "yyyy-mm-dd") -> 2020-11-02 | E24: desktop | F24: Web | G24: Chrome | H24: United States | I24: 120 | J24: 7218 | N24: 2020-11-21 | O24: 2696 | P24: 1068 | Q24: 366 | R24: 4130 | T24: 44156 | U24: 2696 | V24: 1068 | W24: 366 | AG24: 2020-11-19 | AK24: 1 | AM24: 4 | AY24: 10 | BU24: 6 | BX24: 1 | CL24: 2 | CN24: 4 | CQ24: 4 | CZ24: 2 | DN24: 2 | DO24: 2 | DV24: 6 | DY24: 2 | DZ24: 31 | EC24: 2 | ED24: 79
A25: 10295268 | B25: 44137.283 | C25: 44137.396 | D25: =TEXT(C25, "yyyy-mm-dd") -> 2020-11-02 | E25: desktop | F25: Web | G25: Chrome | H25: United States | I25: 164 | J25: 9774 | N25: 2020-11-22 | O25: 1964 | P25: 1464 | R25: 3428 | T25: 44157 | U25: 1964 | V25: 1464 | AG25: 2020-11-20 | AJ25: 2 | AV25: 4 | AY25: 10 | BA25: 2 | BM25: 2 | BO25: 2 | BU25: 16 | CA25: 4 | CN25: 2 | CQ25: 4 | CV25: 2 | DA25: 2 | DG25: 2 | DO25: 2 | DT25: 2 | DV25: 2 | DY25: 2 | DZ25: 38 | ED25: 100
A26: 10295268 | B26: 44137.283 | C26: 44137.408 | D26: =TEXT(C26, "yyyy-mm-dd") -> 2020-11-02 | E26: desktop | F26: Web | G26: Chrome | H26: United States | I26: 137 | J26: 10791 | N26: 2020-11-23 | O26: 3958 | P26: 3746 | Q26: 778 | R26: 8482 | T26: 44158 | U26: 3958 | V26: 3746 | W26: 778 | AG26: 2020-11-21 | AM26: 2 | BA26: 2 | BM26: 6 | BO26: 2 | BU26: 4 | CA26: 4 | CK26: 2 | DG26: 2 | DS26: 4 | DY26: 2 | DZ26: 36 | ED26: 66
A27: 14297513 | B27: 44137.404 | C27: 44137.412 | D27: =TEXT(C27, "yyyy-mm-dd") -> 2020-11-02 | E27: desktop | F27: Web | G27: Chrome | H27: India | I27: 10 | J27: 703 | N27: 2020-11-24 | O27: 4660 | P27: 3621 | Q27: 60 | R27: 8341 | T27: 44159 | U27: 4660 | V27: 3621 | W27: 60 | AG27: 2020-11-22 | AV27: 2 | AY27: 2 | BA27: 2 | BC27: 2 | BM27: 8 | BU27: 6 | CL27: 2 | CZ27: 2 | DN27: 2 | DS27: 2 | DV27: 4 | DY27: 2 | DZ27: 22 | ED27: 58
A28: 10295268 | B28: 44137.283 | C28: 44137.413 | D28: =TEXT(C28, "yyyy-mm-dd") -> 2020-11-02 | E28: desktop | F28: Web | G28: Chrome | H28: United States | I28: 140 | J28: 11255 | N28: 2020-11-25 | O28: 3079 | P28: 1850 | R28: 4929 | T28: 44160 | U28: 3079 | V28: 1850 | AG28: 2020-11-23 | AH28: 2 | AN28: 2 | AV28: 2 | AW28: 2 | AY28: 8 | AZ28: 2 | BA28: 4 | BM28: 2 | BO28: 2 | BS28: 4 | BU28: 14 | BX28: 2 | BY28: 4 | CN28: 2 | CQ28: 2 | DA28: 2 | DG28: 4 | DJ28: 2 | DO28: 8 | DS28: 4 | DV28: 14 | DZ28: 48 | EC28: 2 | ED28: 138
A29: 8620049.7 | B29: 44137.432 | C29: 44137.443 | D29: =TEXT(C29, "yyyy-mm-dd") -> 2020-11-02 | E29: desktop | F29: Web | G29: Chrome | H29: Malaysia | I29: 51 | J29: 1015 | N29: 2020-11-26 | O29: 1361 | P29: 2324 | R29: 3685 | T29: 44161 | U29: 1361 | V29: 2324 | AG29: 2020-11-24 | AS29: 1 | AW29: 2 | AY29: 6 | BA29: 1 | BH29: 2 | BJ29: 1 | BM29: 6 | BO29: 2 | BU29: 17 | BV29: 2 | BX29: 1 | BZ29: 1 | CF29: 2 | CQ29: 2 | CV29: 3 | CZ29: 6 | DB29: 4 | DJ29: 4 | DN29: 4 | DO29: 1 | DS29: 2 | DT29: 2 | DY29: 6 | DZ29: 42 | ED29: 120
A30: 43435922 | B30: 44137.435 | C30: 44137.448 | D30: =TEXT(C30, "yyyy-mm-dd") -> 2020-11-02 | E30: mobile | F30: Android | G30: Chrome | H30: United States | I30: 162 | J30: 1129 | N30: 2020-11-27 | O30: 3748 | P30: 1931 | Q30: 341 | R30: 6020 | T30: 44162 | U30: 3748 | V30: 1931 | W30: 341 | AG30: 2020-11-25 | AH30: 1 | AM30: 1 | AV30: 1 | AX30: 1 | AY30: 7 | BB30: 1 | BH30: 1 | BM30: 2 | BO30: 2 | BS30: 3 | BU30: 6 | BY30: 2 | CA30: 1 | CM30: 1 | CQ30: 2 | DB30: 5 | DJ30: 2 | DO30: 12 | DP30: 1 | DS30: 1 | DT30: 1 | DW30: 1 | DY30: 3 | DZ30: 16 | EC30: 1 | ED30: 75
A31: 3051995.7 | B31: 44137.469 | C31: 44137.477 | D31: =TEXT(C31, "yyyy-mm-dd") -> 2020-11-02 | E31: desktop | F31: Web | G31: Chrome | H31: India | I31: 32 | J31: 667 | N31: 2020-11-28 | O31: 3033 | P31: 3045 | Q31: 14 | R31: 6092 | T31: 44163 | U31: 3033 | V31: 3045 | W31: 14 | AG31: 2020-11-26 | AH31: 1 | AN31: 1 | AY31: 3 | BB31: 1 | BO31: 1 | BU31: 1 | BX31: 1 | CQ31: 1 | CR31: 1 | CS31: 1 | CZ31: 1 | DN31: 1 | DO31: 3 | DY31: 3 | DZ31: 25 | EC31: 2 | ED31: 47
A32: 7186879.8 | B32: 44137.478 | C32: 44137.485 | D32: =TEXT(C32, "yyyy-mm-dd") -> 2020-11-02 | E32: desktop | F32: Web | G32: Firefox | H32: India | I32: 66 | J32: 610 | N32: 2020-11-29 | O32: 2188 | P32: 1397 | Q32: 277 | R32: 3862 | T32: 44164 | U32: 2188 | V32: 1397 | W32: 277 | AG32: 2020-11-27 | AH32: 2 | AM32: 1 | AN32: 1 | AS32: 1 | AV32: 1 | AY32: 1 | BA32: 4 | BB32: 2 | BG32: 1 | BM32: 2 | BU32: 3 | BV32: 1 | BY32: 1 | BZ32: 1 | CA32: 1 | CN32: 1 | CZ32: 1 | DF32: 1 | DG32: 1 | DJ32: 3 | DN32: 2 | DO32: 4 | DQ32: 1 | DT32: 2 | DV32: 2 | DY32: 5 | DZ32: 43 | ED32: 89
A33: 82592842 | B33: 44137.482 | C33: 44137.489 | D33: =TEXT(C33, "yyyy-mm-dd") -> 2020-11-02 | E33: mobile | F33: Web | G33: Chrome | H33: United States | I33: 24 | J33: 580 | N33: 2020-11-30 | O33: 6623 | P33: 5233 | Q33: 7 | R33: 11863 | T33: 44165 | U33: 6623 | V33: 5233 | W33: 7 | AG33: 2020-11-28 | AH33: 1 | AN33: 2 | AS33: 1 | AY33: 5 | BB33: 1 | BC33: 1 | BL33: 1 | BM33: 2 | BO33: 2 | BP33: 1 | BU33: 8 | CA33: 1 | CL33: 1 | CV33: 1 | DC33: 1 | DG33: 1 | DN33: 1 | DR33: 2 | DS33: 1 | DZ33: 35 | ED33: 69
A34: 5299488.1 | B34: 44137.487 | C34: 44137.496 | D34: =TEXT(C34, "yyyy-mm-dd") -> 2020-11-02 | E34: desktop | F34: Windows | G34: Chrome | H34: Italy | I34: 191 | J34: 729 | N34: 2020-12-01 | O34: 3275 | P34: 2891 | Q34: 62 | R34: 6228 | T34: 44166 | U34: 3275 | V34: 2891 | W34: 62 | AG34: 2020-11-29 | AV34: 1 | AY34: 8 | BG34: 2 | BL34: 1 | BO34: 1 | BU34: 5 | CC34: 1 | CL34: 1 | CN34: 1 | CQ34: 1 | CV34: 1 | CW34: 1 | DF34: 1 | DH34: 1 | DJ34: 1 | DN34: 1 | DP34: 1 | DR34: 1 | DS34: 1 | DT34: 1 | DZ34: 15 | EC34: 2 | ED34: 49
A35: 21503965 | B35: 44137.493 | C35: 44137.5 | D35: =TEXT(C35, "yyyy-mm-dd") -> 2020-11-02 | E35: desktop | F35: Web | G35: Chrome | H35: Bangladesh | I35: 38 | J35: 559 | N35: 2020-12-02 | O35: 2418 | P35: 2684 | Q35: 195 | R35: 5297 | T35: 44167 | U35: 2418 | V35: 2684 | W35: 195 | AG35: 2020-11-30 | AK35: 1 | AM35: 1 | AN35: 1 | AY35: 14 | BA35: 1 | BN35: 3 | BO35: 2 | BP35: 1 | BS35: 2 | BU35: 6 | BX35: 2 | CA35: 3 | CD35: 1 | CL35: 2 | CN35: 1 | CQ35: 4 | DA35: 1 | DB35: 1 | DG35: 1 | DH35: 1 | DN35: 3 | DO35: 1 | DS35: 1 | DV35: 1 | DX35: 1 | DY35: 1 | DZ35: 75 | ED35: 132
A36: 6959133.1 | B36: 44137.496 | C36: 44137.504 | D36: =TEXT(C36, "yyyy-mm-dd") -> 2020-11-02 | E36: mobile | F36: Android | G36: Android Webview | H36: United States | I36: 28 | J36: 691 | N36: 2020-12-03 | O36: 2720 | P36: 1499 | Q36: 41 | R36: 4260 | T36: 44168 | U36: 2720 | V36: 1499 | W36: 41 | AG36: 2020-12-01 | AH36: 1 | AN36: 1 | AV36: 2 | AY36: 6 | BA36: 3 | BB36: 4 | BF36: 1 | BM36: 1 | BO36: 2 | BP36: 1 | BS36: 2 | BU36: 5 | BX36: 1 | BY36: 1 | BZ36: 1 | CD36: 1 | CM36: 1 | CN36: 3 | CQ36: 1 | CS36: 1 | CZ36: 1 | DB36: 1 | DJ36: 2 | DO36: 6 | DS36: 1 | DV36: 2 | DY36: 2 | DZ36: 42 | ED36: 96
A37: 40419717 | B37: 44137.261 | C37: 44137.507 | D37: =TEXT(C37, "yyyy-mm-dd") -> 2020-11-02 | E37: mobile | F37: iOS | G37: Safari | H37: Brazil | I37: 192 | J37: 21266 | N37: 2020-12-04 | O37: 3806 | P37: 2520 | Q37: 108 | R37: 6434 | T37: 44169 | U37: 3806 | V37: 2520 | W37: 108 | AG37: 2020-12-02 | AM37: 2 | AS37: 1 | AV37: 1 | AY37: 4 | BE37: 1 | BH37: 1 | BM37: 3 | BS37: 1 | BU37: 13 | BV37: 1 | BZ37: 4 | CA37: 1 | CN37: 1 | CV37: 1 | CZ37: 1 | DA37: 1 | DG37: 1 | DJ37: 1 | DS37: 2 | DV37: 1 | DW37: 1 | DY37: 5 | DZ37: 31 | ED37: 79
A38: 39443463 | B38: 44137.406 | C38: 44137.517 | D38: =TEXT(C38, "yyyy-mm-dd") -> 2020-11-02 | E38: mobile | F38: iOS | G38: Safari | H38: United States | I38: 58 | J38: 9559 | N38: 2020-12-05 | O38: 3625 | P38: 2544 | Q38: 121 | R38: 6290 | T38: 44170 | U38: 3625 | V38: 2544 | W38: 121 | AG38: 2020-12-03 | AH38: 2 | AM38: 1 | AV38: 3 | AY38: 5 | BA38: 1 | BJ38: 1 | BM38: 1 | BO38: 4 | BU38: 10 | BX38: 1 | CA38: 4 | CI38: 1 | CQ38: 2 | CV38: 1 | DB38: 1 | DG38: 3 | DI38: 1 | DN38: 1 | DO38: 1 | DT38: 1 | DV38: 2 | DY38: 2 | DZ38: 36 | ED38: 85
A39: 5963534.5 | B39: 44137.533 | C39: 44137.541 | D39: =TEXT(C39, "yyyy-mm-dd") -> 2020-11-02 | E39: desktop | F39: Web | G39: Chrome | H39: United States | I39: 10 | J39: 662 | N39: 2020-12-06 | O39: 1629 | P39: 649 | Q39: 50 | R39: 2328 | T39: 44171 | U39: 1629 | V39: 649 | W39: 50 | AG39: 2020-12-04 | AH39: 1 | AV39: 2 | AY39: 15 | BA39: 1 | BF39: 1 | BK39: 1 | BM39: 1 | BO39: 2 | BP39: 2 | BU39: 10 | BY39: 1 | CA39: 3 | CN39: 1 | CP39: 1 | CQ39: 1 | CZ39: 2 | DA39: 2 | DN39: 1 | DO39: 2 | DP39: 1 | DQ39: 1 | DV39: 1 | DZ39: 39 | ED39: 92
A40: 5963534.5 | B40: 44137.533 | C40: 44137.544 | D40: =TEXT(C40, "yyyy-mm-dd") -> 2020-11-02 | E40: desktop | F40: Web | G40: Chrome | H40: United States | I40: 10 | J40: 943 | N40: 2020-12-07 | O40: 5885 | P40: 2287 | Q40: 46 | R40: 8218 | T40: 44172 | U40: 5885 | V40: 2287 | W40: 46 | AG40: 2020-12-05 | AN40: 1 | AS40: 3 | AY40: 5 | BA40: 6 | BM40: 2 | BO40: 2 | BU40: 6 | BW40: 1 | BX40: 1 | BY40: 1 | BZ40: 3 | CN40: 3 | CO40: 1 | CQ40: 1 | CZ40: 1 | DC40: 1 | DG40: 3 | DH40: 1 | DN40: 1 | DO40: 2 | DQ40: 1 | DR40: 1 | DS40: 2 | DY40: 3 | DZ40: 32 | ED40: 84
...

Sheet Aggregate data2
A3: Average of time_to_purchase | B3: Column Labels
A4: Row Labels | B4: <Other> | C4: Android Webview | D4: Chrome | E4: Edge | F4: Firefox | G4: Safari | H4: Grand Total | J4: Row Labels | K4: <Other> | L4: Android Webview | M4: Chrome | N4: Edge | O4: Firefox | P4: Safari | Q4: Grand Total | S4: Row Labels | T4: <Other> | U4: Android Webview | V4: Chrome | W4: Edge | X4: Firefox | Y4: Safari | Z4: Grand Total
A5: 2020-11-01 | B5: 7361 | C5: 1482.5 | D5: 1310.5556 | G5: 744 | H5: 1686.3571 | J5: 44136 | K5: 7361 | L5: 1482.5 | M5: 1310.5556 | P5: 744 | Q5: 1686.3571 | S5: 44136 | T5: =K5/60 -> 122.68333 | U5: =L5/60 -> 24.708333 | V5: =M5/60 -> 21.842593 | W5: =N5/60 -> 0 | X5: =O5/60 -> 0 | Y5: =P5/60 -> 12.4 | Z5: =Q5/60 -> 28.105952
A6: 2020-11-02 | B6: 672 | C6: 691 | D6: 4180.375 | E6: 229 | F6: 2580 | G6: 9609.3 | H6: 4934.2245 | J6: 44137 | K6: 672 | L6: 691 | M6: 4180.375 | N6: 229 | O6: 2580 | P6: 9609.3 | Q6: 4934.2245 | S6: 44137 | T6: =K6/60 -> 11.2 | U6: =L6/60 -> 11.516667 | V6: =M6/60 -> 69.672917 | W6: =N6/60 -> 3.8166667 | X6: =O6/60 -> 43 | Y6: =P6/60 -> 160.155 | Z6: =Q6/60 -> 82.237075
A7: 2020-11-03 | B7: 6468 | C7: 2968 | D7: 5544.1389 | G7: 7153.4545 | H7: 5871.6939 | J7: 44138 | K7: 6468 | L7: 2968 | M7: 5544.1389 | P7: 7153.4545 | Q7: 5871.6939 | S7: 44138 | T7: =K7/60 -> 107.8 | U7: =L7/60 -> 49.466667 | V7: =M7/60 -> 92.402315 | W7: =N7/60 -> 0 | X7: =O7/60 -> 0 | Y7: =P7/60 -> 119.22424 | Z7: =Q7/60 -> 97.861565
A8: 2020-11-04 | D8: 6294.1316 | G8: 11278.333 | H8: 6973.7955 | J8: 44139 | M8: 6294.1316 | P8: 11278.333 | Q8: 6973.7955 | S8: 44139 | T8: =K8/60 -> 0 | U8: =L8/60 -> 0 | V8: =M8/60 -> 104.90219 | W8: =N8/60 -> 0 | X8: =O8/60 -> 0 | Y8: =P8/60 -> 187.97222 | Z8: =Q8/60 -> 116.22992
A9: 2020-11-05 | B9: 11876 | D9: 2427.7647 | G9: 1502.375 | H9: 2506.4231 | J9: 44140 | K9: 11876 | M9: 2427.7647 | P9: 1502.375 | Q9: 2506.4231 | S9: 44140 | T9: =K9/60 -> 197.93333 | U9: =L9/60 -> 0 | V9: =M9/60 -> 40.462745 | W9: =N9/60 -> 0 | X9: =O9/60 -> 0 | Y9: =P9/60 -> 25.039583 | Z9: =Q9/60 -> 41.773718
A10: 2020-11-06 | B10: 39676 | C10: 2799 | D10: 4414.85 | E10: 436 | G10: 3590.8462 | H10: 5281 | J10: 44141 | K10: 39676 | L10: 2799 | M10: 4414.85 | N10: 436 | P10: 3590.8462 | Q10: 5281 | S10: 44141 | T10: =K10/60 -> 661.26667 | U10: =L10/60 -> 46.65 | V10: =M10/60 -> 73.580833 | W10: =N10/60 -> 7.2666667 | X10: =O10/60 -> 0 | Y10: =P10/60 -> 59.847436 | Z10: =Q10/60 -> 88.016667
A11: 2020-11-07 | C11: 2630.6667 | D11: 1126.6087 | G11: 2188.8 | H11: 1443.4839 | J11: 44142 | L11: 2630.6667 | M11: 1126.6087 | P11: 2188.8 | Q11: 1443.4839 | S11: 44142 | T11: =K11/60 -> 0 | U11: =L11/60 -> 43.844444 | V11: =M11/60 -> 18.776812 | W11: =N11/60 -> 0 | X11: =O11/60 -> 0 | Y11: =P11/60 -> 36.48 | Z11: =Q11/60 -> 24.058065
A12: 2020-11-08 | C12: 574 | D12: 4331.8095 | G12: 3782.3 | H12: 4042.6562 | J12: 44143 | L12: 574 | M12: 4331.8095 | P12: 3782.3 | Q12: 4042.6562 | S12: 44143 | T12: =K12/60 -> 0 | U12: =L12/60 -> 9.5666667 | V12: =M12/60 -> 72.196825 | W12: =N12/60 -> 0 | X12: =O12/60 -> 0 | Y12: =P12/60 -> 63.038333 | Z12: =Q12/60 -> 67.377604
A13: 2020-11-09 | B13: 9128 | D13: 2184.1765 | G13: 9442.2353 | H13: 4690.5385 | J13: 44144 | K13: 9128 | M13: 2184.1765 | P13: 9442.2353 | Q13: 4690.5385 | S13: 44144 | T13: =K13/60 -> 152.13333 | U13: =L13/60 -> 0 | V13: =M13/60 -> 36.402941 | W13: =N13/60 -> 0 | X13: =O13/60 -> 0 | Y13: =P13/60 -> 157.37059 | Z13: =Q13/60 -> 78.175641
A14: 2020-11-10 | C14: 18351 | D14: 7697.3846 | E14: 6958.5 | F14: 427.66667 | G14: 1508.9286 | H14: 6244.2258 | J14: 44145 | L14: 18351 | M14: 7697.3846 | N14: 6958.5 | O14: 427.66667 | P14: 1508.9286 | Q14: 6244.2258 | S14: 44145 | T14: =K14/60 -> 0 | U14: =L14/60 -> 305.85 | V14: =M14/60 -> 128.28974 | W14: =N14/60 -> 115.975 | X14: =O14/60 -> 7.1277778 | Y14: =P14/60 -> 25.14881 | Z14: =Q14/60 -> 104.07043
A15: 2020-11-11 | B15: 2031 | C15: 338 | D15: 5472.5854 | E15: 923.5 | F15: 895 | G15: 4720.5882 | H15: 4916.4603 | J15: 44146 | K15: 2031 | L15: 338 | M15: 5472.5854 | N15: 923.5 | O15: 895 | P15: 4720.5882 | Q15: 4916.4603 | S15: 44146 | T15: =K15/60 -> 33.85 | U15: =L15/60 -> 5.6333333 | V15: =M15/60 -> 91.209756 | W15: =N15/60 -> 15.391667 | X15: =O15/60 -> 14.916667 | Y15: =P15/60 -> 78.676471 | Z15: =Q15/60 -> 81.941005
A16: 2020-11-12 | B16: 2266 | D16: 6476.8974 | F16: 2072 | G16: 1341.8889 | H16: 5260.5 | J16: 44147 | K16: 2266 | M16: 6476.8974 | O16: 2072 | P16: 1341.8889 | Q16: 5260.5 | S16: 44147 | T16: =K16/60 -> 37.766667 | U16: =L16/60 -> 0 | V16: =M16/60 -> 107.94829 | W16: =N16/60 -> 0 | X16: =O16/60 -> 34.533333 | Y16: =P16/60 -> 22.364815 | Z16: =Q16/60 -> 87.675
A17: 2020-11-13 | B17: 689 | D17: 3032.0317 | F17: 5275 | G17: 9873.2143 | H17: 4243.1266 | J17: 44148 | K17: 689 | M17: 3032.0317 | O17: 5275 | P17: 9873.2143 | Q17: 4243.1266 | S17: 44148 | T17: =K17/60 -> 11.483333 | U17: =L17/60 -> 0 | V17: =M17/60 -> 50.533862 | W17: =N17/60 -> 0 | X17: =O17/60 -> 87.916667 | Y17: =P17/60 -> 164.55357 | Z17: =Q17/60 -> 70.718776
A18: 2020-11-14 | D18: 6662.5185 | G18: 2687 | H18: 6264.9667 | J18: 44149 | M18: 6662.5185 | P18: 2687 | Q18: 6264.9667 | S18: 44149 | T18: =K18/60 -> 0 | U18: =L18/60 -> 0 | V18: =M18/60 -> 111.04198 | W18: =N18/60 -> 0 | X18: =O18/60 -> 0 | Y18: =P18/60 -> 44.783333 | Z18: =Q18/60 -> 104.41611
A19: 2020-11-15 | B19: 2584 | C19: 768 | D19: 925.75 | E19: 438 | F19: 347 | G19: 4069 | H19: 1624.0952 | J19: 44150 | K19: 2584 | L19: 768 | M19: 925.75 | N19: 438 | O19: 347 | P19: 4069 | Q19: 1624.0952 | S19: 44150 | T19: =K19/60 -> 43.066667 | U19: =L19/60 -> 12.8 | V19: =M19/60 -> 15.429167 | W19: =N19/60 -> 7.3 | X19: =O19/60 -> 5.7833333 | Y19: =P19/60 -> 67.816667 | Z19: =Q19/60 -> 27.068254
A20: 2020-11-16 | C20: 529 | D20: 3535.6744 | E20: 12272.5 | G20: 3621 | H20: 3778.3433 | J20: 44151 | L20: 529 | M20: 3535.6744 | N20: 12272.5 | P20: 3621 | Q20: 3778.3433 | S20: 44151 | T20: =K20/60 -> 0 | U20: =L20/60 -> 8.8166667 | V20: =M20/60 -> 58.927907 | W20: =N20/60 -> 204.54167 | X20: =O20/60 -> 0 | Y20: =P20/60 -> 60.35 | Z20: =Q20/60 -> 62.972388
A21: 2020-11-17 | B21: 4263 | C21: 2878.5 | D21: 2855.6111 | G21: 3271.6087 | H21: 2968.0714 | J21: 44152 | K21: 4263 | L21: 2878.5 | M21: 2855.6111 | P21: 3271.6087 | Q21: 2968.0714 | S21: 44152 | T21: =K21/60 -> 71.05 | U21: =L21/60 -> 47.975 | V21: =M21/60 -> 47.593519 | W21: =N21/60 -> 0 | X21: =O21/60 -> 0 | Y21: =P21/60 -> 54.526812 | Z21: =Q21/60 -> 49.467857
A22: 2020-11-18 | B22: 33564 | C22: 3764 | D22: 3009.9556 | E22: 349 | G22: 4168.7778 | H22: 4204.8806 | J22: 44153 | K22: 33564 | L22: 3764 | M22: 3009.9556 | N22: 349 | P22: 4168.7778 | Q22: 4204.8806 | S22: 44153 | T22: =K22/60 -> 559.4 | U22: =L22/60 -> 62.733333 | V22: =M22/60 -> 50.165926 | W22: =N22/60 -> 5.8166667 | X22: =O22/60 -> 0 | Y22: =P22/60 -> 69.47963 | Z22: =Q22/60 -> 70.081343
A23: 2020-11-19 | B23: 510 | C23: 827 | D23: 5135.4222 | G23: 1749 | H23: 3623.2658 | J23: 44154 | K23: 510 | L23: 827 | M23: 5135.4222 | P23: 1749 | Q23: 3623.2658 | S23: 44154 | T23: =K23/60 -> 8.5 | U23: =L23/60 -> 13.783333 | V23: =M23/60 -> 85.59037 | W23: =N23/60 -> 0 | X23: =O23/60 -> 0 | Y23: =P23/60 -> 29.15 | Z23: =Q23/60 -> 60.387764
A24: 2020-11-20 | B24: 458 | C24: 1359 | D24: 6577.0303 | G24: 2449.8077 | H24: 5050.47 | J24: 44155 | K24: 458 | L24: 1359 | M24: 6577.0303 | P24: 2449.8077 | Q24: 5050.47 | S24: 44155 | T24: =K24/60 -> 7.6333333 | U24: =L24/60 -> 22.65 | V24: =M24/60 -> 109.61717 | W24: =N24/60 -> 0 | X24: =O24/60 -> 0 | Y24: =P24/60 -> 40.830128 | Z24: =Q24/60 -> 84.1745
A25: 2020-11-21 | B25: 5331 | C25: 469 | D25: 3591.1458 | F25: 13187 | G25: 1329.6667 | H25: 3428.8636 | J25: 44156 | K25: 5331 | L25: 469 | M25: 3591.1458 | O25: 13187 | P25: 1329.6667 | Q25: 3428.8636 | S25: 44156 | T25: =K25/60 -> 88.85 | U25: =L25/60 -> 7.8166667 | V25: =M25/60 -> 59.852431 | W25: =N25/60 -> 0 | X25: =O25/60 -> 219.78333 | Y25: =P25/60 -> 22.161111 | Z25: =Q25/60 -> 57.147727
A26: 2020-11-22 | B26: 507 | D26: 4343.3 | G26: 4308 | H26: 4201.2759 | J26: 44157 | K26: 507 | M26: 4343.3 | P26: 4308 | Q26: 4201.2759 | S26: 44157 | T26: =K26/60 -> 8.45 | U26: =L26/60 -> 0 | V26: =M26/60 -> 72.388333 | W26: =N26/60 -> 0 | X26: =O26/60 -> 0 | Y26: =P26/60 -> 71.8 | Z26: =Q26/60 -> 70.021264
A27: 2020-11-23 | B27: 2763 | C27: 9841.7857 | D27: 2938.3019 | G27: 2820.6667 | H27: 3620.8043 | J27: 44158 | K27: 2763 | L27: 9841.7857 | M27: 2938.3019 | P27: 2820.6667 | Q27: 3620.8043 | S27: 44158 | T27: =K27/60 -> 46.05 | U27: =L27/60 -> 164.02976 | V27: =M27/60 -> 48.971698 | W27: =N27/60 -> 0 | X27: =O27/60 -> 0 | Y27: =P27/60 -> 47.011111 | Z27: =Q27/60 -> 60.346739
A28: 2020-11-24 | B28: 9365.8 | C28: 6484.8 | D28: 1950.64 | F28: 377 | G28: 4787.303 | H28: 3202.3833 | J28: 44159 | K28: 9365.8 | L28: 6484.8 | M28: 1950.64 | O28: 377 | P28: 4787.303 | Q28: 3202.3833 | S28: 44159 | T28: =K28/60 -> 156.09667 | U28: =L28/60 -> 108.08 | V28: =M28/60 -> 32.510667 | W28: =N28/60 -> 0 | X28: =O28/60 -> 6.2833333 | Y28: =P28/60 -> 79.788384 | Z28: =Q28/60 -> 53.373056
A29: 2020-11-25 | B29: 2475.6667 | C29: 1431 | D29: 6994.3684 | G29: 8937.8571 | H29: 7102.2267 | J29: 44160 | K29: 2475.6667 | L29: 1431 | M29: 6994.3684 | P29: 8937.8571 | Q29: 7102.2267 | S29: 44160 | T29: =K29/60 -> 41.261111 | U29: =L29/60 -> 23.85 | V29: =M29/60 -> 116.57281 | W29: =N29/60 -> 0 | X29: =O29/60 -> 0 | Y29: =P29/60 -> 148.96429 | Z29: =Q29/60 -> 118.37044
A30: 2020-11-26 | C30: 974 | D30: 1825.6176 | F30: 1156 | G30: 5685.7273 | H30: 2696.6809 | J30: 44161 | L30: 974 | M30: 1825.6176 | O30: 1156 | P30: 5685.7273 | Q30: 2696.6809 | S30: 44161 | T30: =K30/60 -> 0 | U30: =L30/60 -> 16.233333 | V30: =M30/60 -> 30.426961 | W30: =N30/60 -> 0 | X30: =O30/60 -> 19.266667 | Y30: =P30/60 -> 94.762121 | Z30: =Q30/60 -> 44.944681
A31: 2020-11-27 | B31: 1368.3333 | D31: 4241.1587 | E31: 1192.6667 | G31: 3771.55 | H31: 3936.0337 | J31: 44162 | K31: 1368.3333 | M31: 4241.1587 | N31: 1192.6667 | P31: 3771.55 | Q31: 3936.0337 | S31: 44162 | T31: =K31/60 -> 22.805556 | U31: =L31/60 -> 0 | V31: =M31/60 -> 70.685979 | W31: =N31/60 -> 19.877778 | X31: =O31/60 -> 0 | Y31: =P31/60 -> 62.859167 | Z31: =Q31/60 -> 65.600562
A32: 2020-11-28 | B32: 1242.3333 | C32: 231 | D32: 2730.3696 | E32: 2213.5 | G32: 4142.1765 | H32: 2962.3043 | J32: 44163 | K32: 1242.3333 | L32: 231 | M32: 2730.3696 | N32: 2213.5 | P32: 4142.1765 | Q32: 2962.3043 | S32: 44163 | T32: =K32/60 -> 20.705556 | U32: =L32/60 -> 3.85 | V32: =M32/60 -> 45.506159 | W32: =N32/60 -> 36.891667 | X32: =O32/60 -> 0 | Y32: =P32/60 -> 69.036275 | Z32: =Q32/60 -> 49.371739
A33: 2020-11-29 | B33: 4803 | C33: 5037 | D33: 5188.1034 | E33: 495 | G33: 3250.8235 | H33: 4409.2653 | J33: 44164 | K33: 4803 | L33: 5037 | M33: 5188.1034 | N33: 495 | P33: 3250.8235 | Q33: 4409.2653 | S33: 44164 | T33: =K33/60 -> 80.05 | U33: =L33/60 -> 83.95 | V33: =M33/60 -> 86.468391 | W33: =N33/60 -> 8.25 | X33: =O33/60 -> 0 | Y33: =P33/60 -> 54.180392 | Z33: =Q33/60 -> 73.487755
A34: 2020-11-30 | B34: 8714.6 | C34: 8025.25 | D34: 5686.1744 | E34: 519 | F34: 946.66667 | G34: 2058.3333 | H34: 4817.947 | J34: 44165 | K34: 8714.6 | L34: 8025.25 | M34: 5686.1744 | N34: 519 | O34: 946.66667 | P34: 2058.3333 | Q34: 4817.947 | S34: 44165 | T34: =K34/60 -> 145.24333 | U34: =L34/60 -> 133.75417 | V34: =M34/60 -> 94.769574 | W34: =N34/60 -> 8.65 | X34: =O34/60 -> 15.777778 | Y34: =P34/60 -> 34.305556 | Z34: =Q34/60 -> 80.299116
A35: 2020-12-01 | B35: 5359.3333 | D35: 4978.5263 | E35: 5647.6667 | F35: 159 | G35: 6976.9375 | H35: 5627.2708 | J35: 44166 | K35: 5359.3333 | M35: 4978.5263 | N35: 5647.6667 | O35: 159 | P35: 6976.9375 | Q35: 5627.2708 | S35: 44166 | T35: =K35/60 -> 89.322222 | U35: =L35/60 -> 0 | V35: =M35/60 -> 82.975439 | W35: =N35/60 -> 94.127778 | X35: =O35/60 -> 2.65 | Y35: =P35/60 -> 116.28229 | Z35: =Q35/60 -> 93.787847
A36: 2020-12-02 | B36: 162 | C36: 6007.1667 | D36: 6897.3269 | F36: 2209.5 | G36: 8471.5556 | H36: 6984.4684 | J36: 44167 | K36: 162 | L36: 6007.1667 | M36: 6897.3269 | O36: 2209.5 | P36: 8471.5556 | Q36: 6984.4684 | S36: 44167 | T36: =K36/60 -> 2.7 | U36: =L36/60 -> 100.11944 | V36: =M36/60 -> 114.95545 | W36: =N36/60 -> 0 | X36: =O36/60 -> 36.825 | Y36: =P36/60 -> 141.19259 | Z36: =Q36/60 -> 116.40781
A37: 2020-12-03 | B37: 43476 | C37: 757 | D37: 3244.5424 | E37: 2808 | F37: 1164 | G37: 6730.4762 | H37: 4495.7294 | J37: 44168 | K37: 43476 | L37: 757 | M37: 3244.5424 | N37: 2808 | O37: 1164 | P37: 6730.4762 | Q37: 4495.7294 | S37: 44168 | T37: =K37/60 -> 724.6 | U37: =L37/60 -> 12.616667 | V37: =M37/60 -> 54.075706 | W37: =N37/60 -> 46.8 | X37: =O37/60 -> 19.4 | Y37: =P37/60 -> 112.1746 | Z37: =Q37/60 -> 74.928824
A38: 2020-12-04 | B38: 3012.5 | C38: 1472 | D38: 3791.3065 | E38: 1059.5 | F38: 537 | G38: 3924.95 | H38: 3607.1413 | J38: 44169 | K38: 3012.5 | L38: 1472 | M38: 3791.3065 | N38: 1059.5 | O38: 537 | P38: 3924.95 | Q38: 3607.1413 | S38: 44169 | T38: =K38/60 -> 50.208333 | U38: =L38/60 -> 24.533333 | V38: =M38/60 -> 63.188441 | W38: =N38/60 -> 17.658333 | X38: =O38/60 -> 8.95 | Y38: =P38/60 -> 65.415833 | Z38: =Q38/60 -> 60.119022
A39: 2020-12-05 | C39: 8239.3333 | D39: 5347.0556 | E39: 932 | F39: 552 | G39: 6047.5417 | H39: 5488.2857 | J39: 44170 | L39: 8239.3333 | M39: 5347.0556 | N39: 932 | O39: 552 | P39: 6047.5417 | Q39: 5488.2857 | S39: 44170 | T39: =K39/60 -> 0 | U39: =L39/60 -> 137.32222 | V39: =M39/60 -> 89.117593 | W39: =N39/60 -> 15.533333 | X39: =O39/60 -> 9.2 | Y39: =P39/60 -> 100.79236 | Z39: =Q39/60 -> 91.471429
A40: 2020-12-06 | B40: 3991 | D40: 4668.25 | F40: 2598 | G40: 4017.8182 | H40: 4426.7317 | J40: 44171 | K40: 3991 | M40: 4668.25 | O40: 2598 | P40: 4017.8182 | Q40: 4426.7317 | S40: 44171 | T40: =K40/60 -> 66.516667 | U40: =L40/60 -> 0 | V40: =M40/60 -> 77.804167 | W40: =N40/60 -> 0 | X40: =O40/60 -> 43.3 | Y40: =P40/60 -> 66.963636 | Z40: =Q40/60 -> 73.778862
A41: 2020-12-07 | D41: 6861.058 | E41: 756 | F41: 1651 | G41: 4061.1071 | H41: 5747.9423 | J41: 44172 | M41: 6861.058 | N41: 756 | O41: 1651 | P41: 4061.1071 | Q41: 5747.9423 | S41: 44172 | T41: =K41/60 -> 0 | U41: =L41/60 -> 0 | V41: =M41/60 -> 114.35097 | W41: =N41/60 -> 12.6 | X41: =O41/60 -> 27.516667 | Y41: =P41/60 -> 67.685119 | Z41: =Q41/60 -> 95.799038
A42: 2020-12-08 | B42: 15152.5 | D42: 5964.2532 | E42: 8781 | F42: 643.66667 | G42: 2961.9333 | H42: 5257.1724 | J42: 44173 | K42: 15152.5 | M42: 5964.2532 | N42: 8781 | O42: 643.66667 | P42: 2961.9333 | Q42: 5257.1724 | S42: 44173 | T42: =K42/60 -> 252.54167 | U42: =L42/60 -> 0 | V42: =M42/60 -> 99.404219 | W42: =N42/60 -> 146.35 | X42: =O42/60 -> 10.727778 | Y42: =P42/60 -> 49.365556 | Z42: =Q42/60 -> 87.61954
...

Sheet Aggregate data3
A3: Average of time_to_purchase | B3: Column Labels
A4: Row Labels | B4: Canada | C4: India | D4: United States | E4: Grand Total | I4: Canada | J4: India | K4: United States | L4: Grand Total | N4: Canada | O4: India | P4: United States | Q4: =L4 -> Grand Total
A5: 2020-11-01 | B5: 601 | D5: 1287 | E5: 1189 | H5: 44136 | I5: 601 | K5: 1287 | L5: 1189 | N5: =I5/60 -> 10.016667 | O5: =J5/60 -> 0 | P5: =K5/60 -> 21.45 | Q5: =L5/60 -> 19.816667
A6: 2020-11-02 | B6: 2794.2857 | C6: 739.57143 | D6: 5380.9583 | E6: 4049.4737 | H6: 44137 | I6: 2794.2857 | J6: 739.57143 | K6: 5380.9583 | L6: 4049.4737 | N6: =I6/60 -> 46.571429 | O6: =J6/60 -> 12.32619 | P6: =K6/60 -> 89.682639 | Q6: =L6/60 -> 67.491228
A7: 2020-11-03 | B7: 1585.5 | C7: 657.75 | D7: 3550.4074 | E7: 3080.697 | H7: 44138 | I7: 1585.5 | J7: 657.75 | K7: 3550.4074 | L7: 3080.697 | N7: =I7/60 -> 26.425 | O7: =J7/60 -> 10.9625 | P7: =K7/60 -> 59.173457 | Q7: =L7/60 -> 51.344949
A8: 2020-11-04 | B8: 1260.6 | C8: 12654.4 | D8: 9626.3636 | E8: 8355.4762 | H8: 44139 | I8: 1260.6 | J8: 12654.4 | K8: 9626.3636 | L8: 8355.4762 | N8: =I8/60 -> 21.01 | O8: =J8/60 -> 210.90667 | P8: =K8/60 -> 160.43939 | Q8: =L8/60 -> 139.25794
A9: 2020-11-05 | B9: 1039.5 | C9: 891 | D9: 3573.3636 | E9: 2877.8667 | H9: 44140 | I9: 1039.5 | J9: 891 | K9: 3573.3636 | L9: 2877.8667 | N9: =I9/60 -> 17.325 | O9: =J9/60 -> 14.85 | P9: =K9/60 -> 59.556061 | Q9: =L9/60 -> 47.964444
A10: 2020-11-06 | B10: 8153.8462 | C10: 1476.5 | D10: 4967.3846 | E10: 5606 | H10: 44141 | I10: 8153.8462 | J10: 1476.5 | K10: 4967.3846 | L10: 5606 | N10: =I10/60 -> 135.89744 | O10: =J10/60 -> 24.608333 | P10: =K10/60 -> 82.789744 | Q10: =L10/60 -> 93.433333
A11: 2020-11-07 | B11: 6801 | C11: 442.5 | D11: 1337.0625 | E11: 1426.8571 | H11: 44142 | I11: 6801 | J11: 442.5 | K11: 1337.0625 | L11: 1426.8571 | N11: =I11/60 -> 113.35 | O11: =J11/60 -> 7.375 | P11: =K11/60 -> 22.284375 | Q11: =L11/60 -> 23.780952
A12: 2020-11-08 | B12: 1740 | C12: 1098.4 | D12: 2586.8235 | E12: 2226.4348 | H12: 44143 | I12: 1740 | J12: 1098.4 | K12: 2586.8235 | L12: 2226.4348 | N12: =I12/60 -> 29 | O12: =J12/60 -> 18.306667 | P12: =K12/60 -> 43.113725 | Q12: =L12/60 -> 37.107246
A13: 2020-11-09 | B13: 6830.5 | C13: 7097.6667 | D13: 3845.6667 | E13: 4713.48 | H13: 44144 | I13: 6830.5 | J13: 7097.6667 | K13: 3845.6667 | L13: 4713.48 | N13: =I13/60 -> 113.84167 | O13: =J13/60 -> 118.29444 | P13: =K13/60 -> 64.094444 | Q13: =L13/60 -> 78.558
A14: 2020-11-10 | B14: 911.33333 | C14: 777.125 | D14: 10966.8 | E14: 7864.4722 | H14: 44145 | I14: 911.33333 | J14: 777.125 | K14: 10966.8 | L14: 7864.4722 | N14: =I14/60 -> 15.188889 | O14: =J14/60 -> 12.952083 | P14: =K14/60 -> 182.78 | Q14: =L14/60 -> 131.07454
A15: 2020-11-11 | B15: 1097.7778 | C15: 8293 | D15: 4235.9259 | E15: 4041.8293 | H15: 44146 | I15: 1097.7778 | J15: 8293 | K15: 4235.9259 | L15: 4041.8293 | N15: =I15/60 -> 18.296296 | O15: =J15/60 -> 138.21667 | P15: =K15/60 -> 70.598765 | Q15: =L15/60 -> 67.363821
A16: 2020-11-12 | B16: 1422.5 | C16: 563.83333 | D16: 2277.5217 | E16: 1890.6774 | H16: 44147 | I16: 1422.5 | J16: 563.83333 | K16: 2277.5217 | L16: 1890.6774 | N16: =I16/60 -> 23.708333 | O16: =J16/60 -> 9.3972222 | P16: =K16/60 -> 37.958696 | Q16: =L16/60 -> 31.51129
A17: 2020-11-13 | B17: 8296.5714 | C17: 3272.5 | D17: 1804.5882 | E17: 2944.9333 | H17: 44148 | I17: 8296.5714 | J17: 3272.5 | K17: 1804.5882 | L17: 2944.9333 | N17: =I17/60 -> 138.27619 | O17: =J17/60 -> 54.541667 | P17: =K17/60 -> 30.076471 | Q17: =L17/60 -> 49.082222
A18: 2020-11-14 | B18: 3651 | C18: 906 | D18: 3200.4 | E18: 3167.6 | H18: 44149 | I18: 3651 | J18: 906 | K18: 3200.4 | L18: 3167.6 | N18: =I18/60 -> 60.85 | O18: =J18/60 -> 15.1 | P18: =K18/60 -> 53.34 | Q18: =L18/60 -> 52.793333
A19: 2020-11-15 | C19: 1066.6667 | D19: 2323.1 | E19: 2033.1538 | H19: 44150 | J19: 1066.6667 | K19: 2323.1 | L19: 2033.1538 | N19: =I19/60 -> 0 | O19: =J19/60 -> 17.777778 | P19: =K19/60 -> 38.718333 | Q19: =L19/60 -> 33.885897
A20: 2020-11-16 | B20: 1086 | C20: 5005.6667 | D20: 3586.6857 | E20: 3448.5957 | H20: 44151 | I20: 1086 | J20: 5005.6667 | K20: 3586.6857 | L20: 3448.5957 | N20: =I20/60 -> 18.1 | O20: =J20/60 -> 83.427778 | P20: =K20/60 -> 59.778095 | Q20: =L20/60 -> 57.476596
A21: 2020-11-17 | B21: 5539.5 | C21: 1346.6 | D21: 3357.7073 | E21: 3312.678 | H21: 44152 | I21: 5539.5 | J21: 1346.6 | K21: 3357.7073 | L21: 3312.678 | N21: =I21/60 -> 92.325 | O21: =J21/60 -> 22.443333 | P21: =K21/60 -> 55.961789 | Q21: =L21/60 -> 55.211299
A22: 2020-11-18 | B22: 4456.5 | C22: 3202.4286 | D22: 5760 | E22: 5235.0204 | H22: 44153 | I22: 4456.5 | J22: 3202.4286 | K22: 5760 | L22: 5235.0204 | N22: =I22/60 -> 74.275 | O22: =J22/60 -> 53.37381 | P22: =K22/60 -> 96 | Q22: =L22/60 -> 87.25034
A23: 2020-11-19 | B23: 517 | C23: 1489.3333 | D23: 3925.5484 | E23: 2889.3191 | H23: 44154 | I23: 517 | J23: 1489.3333 | K23: 3925.5484 | L23: 2889.3191 | N23: =I23/60 -> 8.6166667 | O23: =J23/60 -> 24.822222 | P23: =K23/60 -> 65.425806 | Q23: =L23/60 -> 48.155319
A24: 2020-11-20 | B24: 2852.5 | C24: 3897.875 | D24: 8962.6053 | E24: 6741.7188 | H24: 44155 | I24: 2852.5 | J24: 3897.875 | K24: 8962.6053 | L24: 6741.7188 | N24: =I24/60 -> 47.541667 | O24: =J24/60 -> 64.964583 | P24: =K24/60 -> 149.37675 | Q24: =L24/60 -> 112.36198
A25: 2020-11-21 | C25: 964.5 | D25: 2061.3611 | E25: 1951.675 | H25: 44156 | J25: 964.5 | K25: 2061.3611 | L25: 1951.675 | N25: =I25/60 -> 0 | O25: =J25/60 -> 16.075 | P25: =K25/60 -> 34.356019 | Q25: =L25/60 -> 32.527917
A26: 2020-11-22 | B26: 641 | C26: 1453 | D26: 3023.8182 | E26: 2550.8 | H26: 44157 | I26: 641 | J26: 1453 | K26: 3023.8182 | L26: 2550.8 | N26: =I26/60 -> 10.683333 | O26: =J26/60 -> 24.216667 | P26: =K26/60 -> 50.39697 | Q26: =L26/60 -> 42.513333
A27: 2020-11-23 | B27: 1977.25 | C27: 1635.7143 | D27: 2820.3958 | E27: 2487.1 | H27: 44158 | I27: 1977.25 | J27: 1635.7143 | K27: 2820.3958 | L27: 2487.1 | N27: =I27/60 -> 32.954167 | O27: =J27/60 -> 27.261905 | P27: =K27/60 -> 47.006597 | Q27: =L27/60 -> 41.451667
A28: 2020-11-24 | B28: 2264.5 | C28: 2849.2353 | D28: 3133.2381 | E28: 2978.7692 | H28: 44159 | I28: 2264.5 | J28: 2849.2353 | K28: 3133.2381 | L28: 2978.7692 | N28: =I28/60 -> 37.741667 | O28: =J28/60 -> 47.487255 | P28: =K28/60 -> 52.220635 | Q28: =L28/60 -> 49.646154
A29: 2020-11-25 | B29: 1610.1429 | C29: 14607.167 | D29: 7352.1875 | E29: 7467.2069 | H29: 44160 | I29: 1610.1429 | J29: 14607.167 | K29: 7352.1875 | L29: 7467.2069 | N29: =I29/60 -> 26.835714 | O29: =J29/60 -> 243.45278 | P29: =K29/60 -> 122.53646 | Q29: =L29/60 -> 124.45345
A30: 2020-11-26 | B30: 611 | C30: 1632 | D30: 3884.72 | E30: 3468.3793 | H30: 44161 | I30: 611 | J30: 1632 | K30: 3884.72 | L30: 3468.3793 | N30: =I30/60 -> 10.183333 | O30: =J30/60 -> 27.2 | P30: =K30/60 -> 64.745333 | Q30: =L30/60 -> 57.806322
A31: 2020-11-27 | B31: 2793 | C31: 1330.6667 | D31: 2694.6512 | E31: 2609.6809 | H31: 44162 | I31: 2793 | J31: 1330.6667 | K31: 2694.6512 | L31: 2609.6809 | N31: =I31/60 -> 46.55 | O31: =J31/60 -> 22.177778 | P31: =K31/60 -> 44.910853 | Q31: =L31/60 -> 43.494681
A32: 2020-11-28 | B32: 8261 | C32: 1455.875 | D32: 3330.7143 | E32: 3531.8125 | H32: 44163 | I32: 8261 | J32: 1455.875 | K32: 3330.7143 | L32: 3531.8125 | N32: =I32/60 -> 137.68333 | O32: =J32/60 -> 24.264583 | P32: =K32/60 -> 55.511905 | Q32: =L32/60 -> 58.863542
A33: 2020-11-29 | B33: 1112.875 | C33: 2560.4 | D33: 3807.8667 | E33: 2815.1071 | H33: 44164 | I33: 1112.875 | J33: 2560.4 | K33: 3807.8667 | L33: 2815.1071 | N33: =I33/60 -> 18.547917 | O33: =J33/60 -> 42.673333 | P33: =K33/60 -> 63.464444 | Q33: =L33/60 -> 46.918452
A34: 2020-11-30 | B34: 8536.6429 | C34: 999.33333 | D34: 5042.4 | E34: 5301.9895 | H34: 44165 | I34: 8536.6429 | J34: 999.33333 | K34: 5042.4 | L34: 5301.9895 | N34: =I34/60 -> 142.27738 | O34: =J34/60 -> 16.655556 | P34: =K34/60 -> 84.04 | Q34: =L34/60 -> 88.366491
A35: 2020-12-01 | B35: 10389.667 | C35: 6339.4 | D35: 4274.6667 | E35: 5161.717 | H35: 44166 | I35: 10389.667 | J35: 6339.4 | K35: 4274.6667 | L35: 5161.717 | N35: =I35/60 -> 173.16111 | O35: =J35/60 -> 105.65667 | P35: =K35/60 -> 71.244444 | Q35: =L35/60 -> 86.028616
A36: 2020-12-02 | B36: 2529.25 | C36: 6155.9231 | D36: 10406.323 | E36: 8598.75 | H36: 44167 | I36: 2529.25 | J36: 6155.9231 | K36: 10406.323 | L36: 8598.75 | N36: =I36/60 -> 42.154167 | O36: =J36/60 -> 102.59872 | P36: =K36/60 -> 173.43871 | Q36: =L36/60 -> 143.3125
A37: 2020-12-03 | B37: 1464.2 | C37: 1397.7 | D37: 6869.2222 | E37: 5266.4706 | H37: 44168 | I37: 1464.2 | J37: 1397.7 | K37: 6869.2222 | L37: 5266.4706 | N37: =I37/60 -> 24.403333 | O37: =J37/60 -> 23.295 | P37: =K37/60 -> 114.48704 | Q37: =L37/60 -> 87.77451
... A65: 2020-12-31 | B65: 3921 | C65: 1054 | D65: 1978.4545 | E65: 1985.1429 | H65: 44196 | I65: 3921 | J65: 1054 | K65: 1978.4545 | L65: 1985.1429 | N65: =I65/60 -> 65.35 | O65: =J65/60 -> 17.566667 | P65: =K65/60 -> 32.974242 | Q65: =L65/60 -> 33.085714
A66: 2021-01-01 | C66: 1816 | D66: 1476.4286 | E66: 1518.875 | H66: 44197 | J66: 1816 | K66: 1476.4286 | L66: 1518.875 | N66: =I66/60 -> 0 | O66: =J66/60 -> 30.266667 | P66: =K66/60 -> 24.607143 | Q66: =L66/60 -> 25.314583
A67: 2021-01-02 | B67: 538 | C67: 1157 | D67: 9562.875 | E67: 7214.0909 | H67: 44198 | I67: 538 | J67: 1157 | K67: 9562.875 | L67: 7214.0909 | N67: =I67/60 -> 8.9666667 | O67: =J67/60 -> 19.283333 | P67: =K67/60 -> 159.38125 | Q67: =L67/60 -> 120.23485
A68: 2021-01-03 | D68: 796 | E68: 796 | H68: 44199 | K68: 796 | L68: 796 | N68: =I68/60 -> 0 | O68: =J68/60 -> 0 | P68: =K68/60 -> 13.266667 | Q68: =L68/60 -> 13.266667
